[2025-10-25T16:15:45.594+0200] {taskinstance.py:1956} INFO - Dependencies all met for dep_context=non-requeueable deps ti=<TaskInstance: order_monitoring_dag.run_dbt_models scheduled__2025-10-25T13:00:00+00:00 [queued]>
[2025-10-25T16:15:45.596+0200] {taskinstance.py:1956} INFO - Dependencies all met for dep_context=requeueable deps ti=<TaskInstance: order_monitoring_dag.run_dbt_models scheduled__2025-10-25T13:00:00+00:00 [queued]>
[2025-10-25T16:15:45.596+0200] {taskinstance.py:2170} INFO - Starting attempt 1 of 1
[2025-10-25T16:15:45.600+0200] {taskinstance.py:2191} INFO - Executing <Task(BashOperator): run_dbt_models> on 2025-10-25 13:00:00+00:00
[2025-10-25T16:15:45.603+0200] {standard_task_runner.py:60} INFO - Started process 71586 to run task
[2025-10-25T16:15:45.606+0200] {standard_task_runner.py:87} INFO - Running: ['airflow', 'tasks', 'run', 'order_monitoring_dag', 'run_dbt_models', 'scheduled__2025-10-25T13:00:00+00:00', '--job-id', '3', '--raw', '--subdir', 'DAGS_FOLDER/order_monitor_dag.py', '--cfg-path', '/var/folders/wk/chr7_t6j60nghq43c2zs3mlw0000gn/T/tmpwxa9stat']
[2025-10-25T16:15:45.607+0200] {standard_task_runner.py:88} INFO - Job 3: Subtask run_dbt_models
[2025-10-25T16:15:45.627+0200] {task_command.py:423} INFO - Running <TaskInstance: order_monitoring_dag.run_dbt_models scheduled__2025-10-25T13:00:00+00:00 [running]> on host host-002.lan
[2025-10-25T16:15:45.645+0200] {taskinstance.py:2480} INFO - Exporting env vars: AIRFLOW_CTX_DAG_EMAIL='daaloul.youssef@outlook.fr' AIRFLOW_CTX_DAG_OWNER='airflow' AIRFLOW_CTX_DAG_ID='order_monitoring_dag' AIRFLOW_CTX_TASK_ID='run_dbt_models' AIRFLOW_CTX_EXECUTION_DATE='2025-10-25T13:00:00+00:00' AIRFLOW_CTX_TRY_NUMBER='1' AIRFLOW_CTX_DAG_RUN_ID='scheduled__2025-10-25T13:00:00+00:00'
[2025-10-25T16:15:45.646+0200] {subprocess.py:63} INFO - Tmp dir root location: /var/folders/wk/chr7_t6j60nghq43c2zs3mlw0000gn/T
[2025-10-25T16:15:45.647+0200] {subprocess.py:75} INFO - Running command: ['/bin/bash', '-c', 'source "/Users/youssefdaaloul/venv/dbt_snowflake/airflow_venv_39/bin/activate" && cd "/Users/youssefdaaloul/venv/dbt_snowflake/dbt_ecommerce" && dbt run']
[2025-10-25T16:15:45.650+0200] {subprocess.py:86} INFO - Output:
[2025-10-25T16:15:45.659+0200] {subprocess.py:93} INFO - /bin/bash: dbt: command not found
[2025-10-25T16:15:45.659+0200] {subprocess.py:97} INFO - Command exited with return code 127
[2025-10-25T16:15:45.663+0200] {taskinstance.py:2698} ERROR - Task failed with exception
Traceback (most recent call last):
  File "/Users/youssefdaaloul/venv/dbt_snowflake/airflow_venv_39/lib/python3.11/site-packages/airflow/models/taskinstance.py", line 433, in _execute_task
    result = execute_callable(context=context, **execute_callable_kwargs)
             ^^^^^^^^^^^^^^^^^^^^^^^^^^^^^^^^^^^^^^^^^^^^^^^^^^^^^^^^^^^^
  File "/Users/youssefdaaloul/venv/dbt_snowflake/airflow_venv_39/lib/python3.11/site-packages/airflow/operators/bash.py", line 212, in execute
    raise AirflowException(
airflow.exceptions.AirflowException: Bash command failed. The command returned a non-zero exit code 127.
[2025-10-25T16:15:45.664+0200] {taskinstance.py:1138} INFO - Marking task as FAILED. dag_id=order_monitoring_dag, task_id=run_dbt_models, execution_date=20251025T130000, start_date=20251025T141545, end_date=20251025T141545
[2025-10-25T16:15:45.671+0200] {logging_mixin.py:188} WARNING - /Users/youssefdaaloul/venv/dbt_snowflake/airflow_venv_39/lib/python3.11/site-packages/airflow/utils/email.py:154 RemovedInAirflow3Warning: Fetching SMTP credentials from configuration variables will be deprecated in a future release. Please set credentials using a connection instead.
[2025-10-25T16:15:45.672+0200] {configuration.py:1046} WARNING - section/key [smtp/smtp_user] not found in config
[2025-10-25T16:15:45.672+0200] {email.py:270} INFO - Email alerting: attempt 1
[2025-10-25T16:15:45.674+0200] {configuration.py:1046} WARNING - section/key [smtp/smtp_user] not found in config
[2025-10-25T16:15:45.675+0200] {email.py:270} INFO - Email alerting: attempt 1
[2025-10-25T16:15:45.675+0200] {taskinstance.py:826} ERROR - Failed to send email to: ['daaloul.youssef@outlook.fr']
Traceback (most recent call last):
  File "/Users/youssefdaaloul/venv/dbt_snowflake/airflow_venv_39/lib/python3.11/site-packages/airflow/models/taskinstance.py", line 2334, in _run_raw_task
    self._execute_task_with_callbacks(context, test_mode, session=session)
  File "/Users/youssefdaaloul/venv/dbt_snowflake/airflow_venv_39/lib/python3.11/site-packages/airflow/models/taskinstance.py", line 2499, in _execute_task_with_callbacks
    result = self._execute_task(context, task_orig)
             ^^^^^^^^^^^^^^^^^^^^^^^^^^^^^^^^^^^^^^
  File "/Users/youssefdaaloul/venv/dbt_snowflake/airflow_venv_39/lib/python3.11/site-packages/airflow/models/taskinstance.py", line 2516, in _execute_task
    return _execute_task(self, context, task_orig)
           ^^^^^^^^^^^^^^^^^^^^^^^^^^^^^^^^^^^^^^^
  File "/Users/youssefdaaloul/venv/dbt_snowflake/airflow_venv_39/lib/python3.11/site-packages/airflow/models/taskinstance.py", line 433, in _execute_task
    result = execute_callable(context=context, **execute_callable_kwargs)
             ^^^^^^^^^^^^^^^^^^^^^^^^^^^^^^^^^^^^^^^^^^^^^^^^^^^^^^^^^^^^
  File "/Users/youssefdaaloul/venv/dbt_snowflake/airflow_venv_39/lib/python3.11/site-packages/airflow/operators/bash.py", line 212, in execute
    raise AirflowException(
airflow.exceptions.AirflowException: Bash command failed. The command returned a non-zero exit code 127.

During handling of the above exception, another exception occurred:

Traceback (most recent call last):
  File "/Users/youssefdaaloul/venv/dbt_snowflake/airflow_venv_39/lib/python3.11/site-packages/airflow/models/taskinstance.py", line 1000, in _email_alert
    send_email(task.email, subject, html_content)
  File "/Users/youssefdaaloul/venv/dbt_snowflake/airflow_venv_39/lib/python3.11/site-packages/airflow/utils/email.py", line 80, in send_email
    return backend(
           ^^^^^^^^
  File "/Users/youssefdaaloul/venv/dbt_snowflake/airflow_venv_39/lib/python3.11/site-packages/airflow/utils/email.py", line 154, in send_email_smtp
    send_mime_email(e_from=mail_from, e_to=recipients, mime_msg=msg, conn_id=conn_id, dryrun=dryrun)
  File "/Users/youssefdaaloul/venv/dbt_snowflake/airflow_venv_39/lib/python3.11/site-packages/airflow/utils/email.py", line 272, in send_mime_email
    smtp_conn = _get_smtp_connection(smtp_host, smtp_port, smtp_timeout, smtp_ssl)
                ^^^^^^^^^^^^^^^^^^^^^^^^^^^^^^^^^^^^^^^^^^^^^^^^^^^^^^^^^^^^^^^^^^
  File "/Users/youssefdaaloul/venv/dbt_snowflake/airflow_venv_39/lib/python3.11/site-packages/airflow/utils/email.py", line 316, in _get_smtp_connection
    return smtplib.SMTP(host=host, port=port, timeout=timeout)
           ^^^^^^^^^^^^^^^^^^^^^^^^^^^^^^^^^^^^^^^^^^^^^^^^^^^
  File "/opt/homebrew/Cellar/python@3.11/3.11.14/Frameworks/Python.framework/Versions/3.11/lib/python3.11/smtplib.py", line 255, in __init__
    (code, msg) = self.connect(host, port)
                  ^^^^^^^^^^^^^^^^^^^^^^^^
  File "/opt/homebrew/Cellar/python@3.11/3.11.14/Frameworks/Python.framework/Versions/3.11/lib/python3.11/smtplib.py", line 341, in connect
    self.sock = self._get_socket(host, port, self.timeout)
                ^^^^^^^^^^^^^^^^^^^^^^^^^^^^^^^^^^^^^^^^^^
  File "/opt/homebrew/Cellar/python@3.11/3.11.14/Frameworks/Python.framework/Versions/3.11/lib/python3.11/smtplib.py", line 312, in _get_socket
    return socket.create_connection((host, port), timeout,
           ^^^^^^^^^^^^^^^^^^^^^^^^^^^^^^^^^^^^^^^^^^^^^^^
  File "/opt/homebrew/Cellar/python@3.11/3.11.14/Frameworks/Python.framework/Versions/3.11/lib/python3.11/socket.py", line 863, in create_connection
    raise exceptions[0]
  File "/opt/homebrew/Cellar/python@3.11/3.11.14/Frameworks/Python.framework/Versions/3.11/lib/python3.11/socket.py", line 848, in create_connection
    sock.connect(sa)
ConnectionRefusedError: [Errno 61] Connection refused

During handling of the above exception, another exception occurred:

Traceback (most recent call last):
  File "/Users/youssefdaaloul/venv/dbt_snowflake/airflow_venv_39/lib/python3.11/site-packages/airflow/models/taskinstance.py", line 824, in _handle_failure
    task_instance.email_alert(error, failure_context["task"])
  File "/Users/youssefdaaloul/venv/dbt_snowflake/airflow_venv_39/lib/python3.11/site-packages/airflow/models/taskinstance.py", line 2946, in email_alert
    _email_alert(task_instance=self, exception=exception, task=task)
  File "/Users/youssefdaaloul/venv/dbt_snowflake/airflow_venv_39/lib/python3.11/site-packages/airflow/models/taskinstance.py", line 1002, in _email_alert
    send_email(task.email, subject, html_content_err)
  File "/Users/youssefdaaloul/venv/dbt_snowflake/airflow_venv_39/lib/python3.11/site-packages/airflow/utils/email.py", line 80, in send_email
    return backend(
           ^^^^^^^^
  File "/Users/youssefdaaloul/venv/dbt_snowflake/airflow_venv_39/lib/python3.11/site-packages/airflow/utils/email.py", line 154, in send_email_smtp
    send_mime_email(e_from=mail_from, e_to=recipients, mime_msg=msg, conn_id=conn_id, dryrun=dryrun)
  File "/Users/youssefdaaloul/venv/dbt_snowflake/airflow_venv_39/lib/python3.11/site-packages/airflow/utils/email.py", line 272, in send_mime_email
    smtp_conn = _get_smtp_connection(smtp_host, smtp_port, smtp_timeout, smtp_ssl)
                ^^^^^^^^^^^^^^^^^^^^^^^^^^^^^^^^^^^^^^^^^^^^^^^^^^^^^^^^^^^^^^^^^^
  File "/Users/youssefdaaloul/venv/dbt_snowflake/airflow_venv_39/lib/python3.11/site-packages/airflow/utils/email.py", line 316, in _get_smtp_connection
    return smtplib.SMTP(host=host, port=port, timeout=timeout)
           ^^^^^^^^^^^^^^^^^^^^^^^^^^^^^^^^^^^^^^^^^^^^^^^^^^^
  File "/opt/homebrew/Cellar/python@3.11/3.11.14/Frameworks/Python.framework/Versions/3.11/lib/python3.11/smtplib.py", line 255, in __init__
    (code, msg) = self.connect(host, port)
                  ^^^^^^^^^^^^^^^^^^^^^^^^
  File "/opt/homebrew/Cellar/python@3.11/3.11.14/Frameworks/Python.framework/Versions/3.11/lib/python3.11/smtplib.py", line 341, in connect
    self.sock = self._get_socket(host, port, self.timeout)
                ^^^^^^^^^^^^^^^^^^^^^^^^^^^^^^^^^^^^^^^^^^
  File "/opt/homebrew/Cellar/python@3.11/3.11.14/Frameworks/Python.framework/Versions/3.11/lib/python3.11/smtplib.py", line 312, in _get_socket
    return socket.create_connection((host, port), timeout,
           ^^^^^^^^^^^^^^^^^^^^^^^^^^^^^^^^^^^^^^^^^^^^^^^
  File "/opt/homebrew/Cellar/python@3.11/3.11.14/Frameworks/Python.framework/Versions/3.11/lib/python3.11/socket.py", line 863, in create_connection
    raise exceptions[0]
  File "/opt/homebrew/Cellar/python@3.11/3.11.14/Frameworks/Python.framework/Versions/3.11/lib/python3.11/socket.py", line 848, in create_connection
    sock.connect(sa)
ConnectionRefusedError: [Errno 61] Connection refused
[2025-10-25T16:15:45.680+0200] {standard_task_runner.py:107} ERROR - Failed to execute job 3 for task run_dbt_models (Bash command failed. The command returned a non-zero exit code 127.; 71586)
[2025-10-25T16:15:45.701+0200] {local_task_job_runner.py:234} INFO - Task exited with return code 1
[2025-10-25T16:15:45.708+0200] {taskinstance.py:3280} INFO - 0 downstream tasks scheduled from follow-on schedule check
